<?xml version="1.0" ?>
<!-- =================================================================================== -->
<!-- |    This document was autogenerated by xacro from motomini.urdf.xacro            | -->
<!-- |    EDITING THIS FILE BY HAND IS NOT RECOMMENDED                                 | -->
<!-- =================================================================================== -->
<robot name="motoman_motomini" xmlns:xacro="http://ros.org/wiki/xacro">
  <material name="black">
    <color rgba="0.0 0.0 0.0 1.0"/>
  </material>
  <material name="blue">
    <color rgba="0.0 0.0 0.8 1.0"/>
  </material>
  <material name="green">
    <color rgba="0.0 0.8 0.0 1.0"/>
  </material>
  <material name="grey">
    <color rgba="0.2 0.2 0.2 1.0"/>
  </material>
  <material name="orange">
    <color rgba="1.0 0.423529411765 0.0392156862745 1.0"/>
  </material>
  <material name="brown">
    <color rgba="0.870588235294 0.811764705882 0.764705882353 1.0"/>
  </material>
  <material name="red">
    <color rgba="0.8 0.0 0.0 1.0"/>
  </material>
  <material name="white">
    <color rgba="1.0 1.0 1.0 1.0"/>
  </material>
  <material name="yaskawa_blue">
    <color rgba="0.12941 0.14902 0.74902 1"/>
  </material>
  <link name="base_link">
    <visual>
      <geometry>
        <mesh filename="package://motoman_description/meshes/motomini/visual/base_link.stl"/>
      </geometry>
      <material name="yaskawa_blue"/>
    </visual>
    <collision>
      <geometry>
        <mesh filename="package://motoman_description/meshes/motomini/collision/base_link.stl"/>
      </geometry>
    </collision>
    <inertial>
      <origin rpy="0 0 0" xyz="0 0 0"/>
      <mass value="1.57894736842"/>
      <inertia ixx="0.00335213815789" ixy="0" ixz="0" iyy="0.00796650131579" iyz="0" izz="0.00866067894737"/>
    </inertial>
  </link>
  <link name="link_1_s">
    <visual>
      <geometry>
        <mesh filename="package://motoman_description/meshes/motomini/visual/link_1_s.stl"/>
      </geometry>
      <material name="yaskawa_blue"/>
    </visual>
    <collision>
      <geometry>
        <mesh filename="package://motoman_description/meshes/motomini/collision/link_1_s.stl"/>
      </geometry>
    </collision>
    <inertial>
      <origin rpy="0 0 0" xyz="0 0 0"/>
      <mass value="1.57894736842"/>
      <inertia ixx="0.00457279605263" ixy="0" ixz="0" iyy="0.00462006578947" iyz="0" izz="0.00377384868421"/>
    </inertial>
  </link>
  <link name="link_2_l">
    <visual>
      <geometry>
        <mesh filename="package://motoman_description/meshes/motomini/visual/link_2_l.stl"/>
      </geometry>
      <material name="yaskawa_blue"/>
    </visual>
    <collision>
      <geometry>
        <mesh filename="package://motoman_description/meshes/motomini/collision/link_2_l.stl"/>
      </geometry>
    </collision>
    <inertial>
      <origin rpy="0 0 0" xyz="0 0 0"/>
      <mass value="1.57894736842"/>
      <inertia ixx="0.00386766842105" ixy="0" ixz="0" iyy="0.0101251894737" iyz="0" izz="0.00928168947368"/>
    </inertial>
  </link>
  <link name="link_3_u">
    <visual>
      <geometry>
        <mesh filename="package://motoman_description/meshes/motomini/visual/link_3_u.stl"/>
      </geometry>
      <material name="yaskawa_blue"/>
    </visual>
    <collision>
      <geometry>
        <mesh filename="package://motoman_description/meshes/motomini/collision/link_3_u.stl"/>
      </geometry>
    </collision>
    <inertial>
      <origin rpy="0 0 0" xyz="0 0 0"/>
      <mass value="0.526315789474"/>
      <inertia ixx="0.000554353070175" ixy="0" ixz="0" iyy="0.000830310964912" iyz="0" izz="0.000743414035088"/>
    </inertial>
  </link>
  <link name="link_4_r">
    <visual>
      <geometry>
        <mesh filename="package://motoman_description/meshes/motomini/visual/link_4_r.stl"/>
      </geometry>
      <material name="yaskawa_blue"/>
    </visual>
    <collision>
      <geometry>
        <mesh filename="package://motoman_description/meshes/motomini/collision/link_4_r.stl"/>
      </geometry>
    </collision>
    <inertial>
      <origin rpy="0 0 0" xyz="0 0 0"/>
      <mass value="0.526315789474"/>
      <inertia ixx="0.00194845350877" ixy="0" ixz="0" iyy="0.00193777412281" iyz="0" izz="0.000769363596491"/>
    </inertial>
  </link>
  <link name="link_5_b">
    <visual>
      <geometry>
        <mesh filename="package://motoman_description/meshes/motomini/visual/link_5_b.stl"/>
      </geometry>
      <material name="yaskawa_blue"/>
    </visual>
    <collision>
      <geometry>
        <mesh filename="package://motoman_description/meshes/motomini/collision/link_5_b.stl"/>
      </geometry>
    </collision>
    <inertial>
      <origin rpy="0 0 0" xyz="0 0 0"/>
      <mass value="0.526315789474"/>
      <inertia ixx="0.000357912719298" ixy="0" ixz="0" iyy="0.000421600877193" iyz="0" izz="0.000493512719298"/>
    </inertial>
  </link>
  <link name="link_6_t">
    <visual>
      <geometry>
        <mesh filename="package://motoman_description/meshes/motomini/visual/link_6_t.stl"/>
      </geometry>
      <material name="yaskawa_blue"/>
    </visual>
    <collision>
      <geometry>
        <mesh filename="package://motoman_description/meshes/motomini/collision/link_6_t.stl"/>
      </geometry>
    </collision>
    <inertial>
      <origin rpy="0 0 0" xyz="0 0 0"/>
      <mass value="0.684210526316"/>
      <inertia ixx="7.1899122807e-05" ixy="0" ixz="0" iyy="7.1899122807e-05" iyz="0" izz="0.000102631578947"/>
    </inertial>
  </link>
  <link name="tool0"/>
  <!-- end of link list -->
  <joint name="joint_1_s" type="revolute">
    <parent link="base_link"/>
    <child link="link_1_s"/>
    <origin rpy="0 0 0" xyz="0 0 0.103"/>
    <axis xyz="0 0 1"/>
    <limit effort="0.12" lower="-2.967" upper="2.967" velocity="5.4977"/>
  </joint>
  <joint name="joint_2_l" type="revolute">
    <parent link="link_1_s"/>
    <child link="link_2_l"/>
    <origin rpy="0 0 0" xyz="0.020 0 0"/>
    <axis xyz="0 1 0"/>
    <limit effort="0.12" lower="-1.4835" upper="1.5707" velocity="5.4977"/>
  </joint>
  <joint name="joint_3_u" type="revolute">
    <parent link="link_2_l"/>
    <child link="link_3_u"/>
    <origin rpy="0 0 0" xyz="0 0 0.165"/>
    <axis xyz="0 -1 0"/>
    <limit effort="0.12" lower="-0.8726" upper="1.5707" velocity="7.3304"/>
  </joint>
  <joint name="joint_4_r" type="revolute">
    <parent link="link_3_u"/>
    <child link="link_4_r"/>
    <origin rpy="0 0 0" xyz="0.165 0 0"/>
    <axis xyz="-1 0 0"/>
    <limit effort="0.07" lower="-2.4434" upper="2.4434" velocity="10.4719"/>
  </joint>
  <joint name="joint_5_b" type="revolute">
    <parent link="link_4_r"/>
    <child link="link_5_b"/>
    <origin rpy="0 0 0" xyz="0 0 0"/>
    <axis xyz="0 -1 0"/>
    <limit effort="0.07" lower="-0.5235" upper="3.6651" velocity="10.4719"/>
  </joint>
  <joint name="joint_6_t" type="revolute">
    <parent link="link_5_b"/>
    <child link="link_6_t"/>
    <origin rpy="0 0 0" xyz="0 0 0"/>
    <axis xyz="0 0 1"/>
    <limit effort="0.07" lower="-6.2831" upper="6.2831" velocity="10.4719"/>
  </joint>
  <joint name="joint_6_t-tool0" type="fixed">
    <origin rpy="3.14159265359 0 0" xyz="0 0 -0.040 "/>
    <parent link="link_6_t"/>
    <child link="tool0"/>
  </joint>
  <!-- end of joint list -->
  <!-- ROS base_link to Robot Manufacturer World Coordinates transform -->
  <link name="base"/>
  <joint name="base_link-base" type="fixed">
    <origin rpy="0 0 0" xyz="0 0 0.103"/>
    <parent link="base_link"/>
    <child link="base"/>
  </joint>
  <transmission name="transmission_1_s">
    <type>transmission_interface/SimpleTransmission</type>
    <joint name="joint_1_s">
      <hardwareInterface>hardware_interface/PositionJointInterface</hardwareInterface>
    </joint>
    <actuator name="motor_1_s">
      <hardwareInterface>hardware_interface/PositionJointInterface</hardwareInterface>
      <mechanicalReduction>300</mechanicalReduction>
    </actuator>
  </transmission>
  <transmission name="transmission_2_l">
    <type>transmission_interface/SimpleTransmission</type>
    <joint name="joint_2_l">
      <hardwareInterface>hardware_interface/PositionJointInterface</hardwareInterface>
    </joint>
    <actuator name="motor_2_l">
      <hardwareInterface>hardware_interface/PositionJointInterface</hardwareInterface>
      <mechanicalReduction>300</mechanicalReduction>
    </actuator>
  </transmission>
  <transmission name="transmission_3_u">
    <type>transmission_interface/SimpleTransmission</type>
    <joint name="joint_3_u">
      <hardwareInterface>hardware_interface/PositionJointInterface</hardwareInterface>
    </joint>
    <actuator name="motor_3_u">
      <hardwareInterface>hardware_interface/PositionJointInterface</hardwareInterface>
      <mechanicalReduction>50</mechanicalReduction>
    </actuator>
  </transmission>
  <transmission name="transmission_4_r">
    <type>transmission_interface/SimpleTransmission</type>
    <joint name="joint_4_r">
      <hardwareInterface>hardware_interface/PositionJointInterface</hardwareInterface>
    </joint>
    <actuator name="motor_4_r">
      <hardwareInterface>hardware_interface/PositionJointInterface</hardwareInterface>
      <mechanicalReduction>30</mechanicalReduction>
    </actuator>
  </transmission>
  <transmission name="transmission_5_b">
    <type>transmission_interface/SimpleTransmission</type>
    <joint name="joint_5_b">
      <hardwareInterface>hardware_interface/PositionJointInterface</hardwareInterface>
    </joint>
    <actuator name="motor_5_b">
      <hardwareInterface>hardware_interface/PositionJointInterface</hardwareInterface>
      <mechanicalReduction>30</mechanicalReduction>
    </actuator>
  </transmission>
  <transmission name="transmission_6_t">
    <type>transmission_interface/SimpleTransmission</type>
    <joint name="joint_6_t">
      <hardwareInterface>hardware_interface/PositionJointInterface</hardwareInterface>
    </joint>
    <actuator name="motor_6_t">
      <hardwareInterface>hardware_interface/PositionJointInterface</hardwareInterface>
      <mechanicalReduction>10</mechanicalReduction>
    </actuator>
  </transmission>
  <!-- gazebo -->
  <gazebo>
    <plugin filename="libgazebo_ros_control.so" name="gazebo_ros_control">
      <robotSimType>gazebo_ros_control/DefaultRobotHWSim</robotSimType>
    </plugin>
  </gazebo>
  <gazebo reference="base_link">
    <mu1>0.2</mu1>
    <mu2>0.2</mu2>
    <selfCollide>false</selfCollide>
    <material>Gazebo/Blue</material>
  </gazebo>
  <gazebo reference="link_1_s">
    <mu1>0.2</mu1>
    <mu2>0.2</mu2>
    <selfCollide>false</selfCollide>
    <material>Gazebo/Blue</material>
  </gazebo>
  <gazebo reference="link_2_l">
    <mu1>0.2</mu1>
    <mu2>0.2</mu2>
    <selfCollide>false</selfCollide>
    <material>Gazebo/Blue</material>
  </gazebo>
  <gazebo reference="link_3_u">
    <mu1>0.2</mu1>
    <mu2>0.2</mu2>
    <selfCollide>false</selfCollide>
    <material>Gazebo/Blue</material>
  </gazebo>
  <gazebo reference="link_4_r">
    <mu1>0.2</mu1>
    <mu2>0.2</mu2>
    <selfCollide>false</selfCollide>
    <material>Gazebo/Blue</material>
  </gazebo>
  <gazebo reference="link_5_b">
    <mu1>0.2</mu1>
    <mu2>0.2</mu2>
    <selfCollide>false</selfCollide>
    <material>Gazebo/Blue</material>
  </gazebo>
  <gazebo reference="link_6_t">
    <mu1>0.2</mu1>
    <mu2>0.2</mu2>
    <selfCollide>false</selfCollide>
    <material>Gazebo/Blue</material>
  </gazebo>
  <link name="world"/>
  <joint name="world" type="fixed">
    <origin rpy="0 0 0" xyz="0 0 0.067"/>
    <parent link="world"/>
    <child link="base_link"/>
  </joint>
</robot>

